Workbook

Sheet Client Onboarding
A1: CLIENT ONBOARDING - Application Register
A3: Application ID | B3: Customer ID | C3: Customer Name | D3: Customer Type | E3: Documents Submitted | F3: Verification Status | G3: Risk Category | H3: Application Date | I3: Decision Date | J3: Turnaround Time (Days) | K3: SLA Target (Days) | L3: SLA Met | M3: Final Status | N3: Rejection Reason
A4: APP0001 | B4: CUST0001 | C4: Priya Mehta | D4: Individual | E4: PAN, Aadhaar, Address Proof | F4: Verified | G4: Low | H4: 2025-12-18 | I4: 2025-12-20 | J4: =IF(I4="","",I4-H4) -> 2 | K4: 3 | L4: =IF(J4="","N/A",IF(J4<=K4,"Yes","No")) -> Yes | M4: Approved
A5: APP0002 | B5: CUST0002 | C5: Nova Textiles Ltd | D5: Corporate | E5: PAN, COI, Board Resolution, Address Proof | F5: Verified | G5: Low | H5: 2025-12-06 | I5: 2025-12-07 | J5: =IF(I5="","",I5-H5) -> 1 | K5: 3 | L5: =IF(J5="","N/A",IF(J5<=K5,"Yes","No")) -> Yes | M5: Approved
A6: APP0003 | B6: CUST0003 | C6: Rahul Rao | D6: Individual | E6: PAN, Aadhaar, Photo | F6: Pending | G6: Medium | H6: 2025-12-19 | J6: =IF(I6="","",I6-H6) | K6: 5 | L6: =IF(J6="","N/A",IF(J6<=K6,"Yes","No")) -> N/A | M6: Pending
A7: APP0004 | B7: CUST0004 | C7: Swati Mehta | D7: Individual | E7: PAN, Aadhaar, Photo, Income Proof | F7: Verified | G7: Low | H7: 2025-11-07 | I7: 2025-11-12 | J7: =IF(I7="","",I7-H7) -> 5 | K7: 3 | L7: =IF(J7="","N/A",IF(J7<=K7,"Yes","No")) -> No | M7: Approved
A8: APP0005 | B8: CUST0005 | C8: Tanvi Saxena | D8: Individual | E8: Aadhaar, Photo (PAN missing) | F8: Incomplete | G8: Low | H8: 2025-11-06 | J8: =IF(I8="","",I8-H8) | K8: 3 | L8: =IF(J8="","N/A",IF(J8<=K8,"Yes","No")) -> N/A | M8: Pending
A9: APP0006 | B9: CUST0006 | C9: Radhika Malhotra | D9: Individual | E9: PAN, Aadhaar, Photo | F9: Verified | G9: Medium | H9: 2025-11-03 | I9: 2025-11-09 | J9: =IF(I9="","",I9-H9) -> 6 | K9: 5 | L9: =IF(J9="","N/A",IF(J9<=K9,"Yes","No")) -> No | M9: Approved
A10: APP0007 | B10: CUST0007 | C10: Rahul Iyer | D10: Individual | E10: Aadhaar, Photo (PAN missing) | F10: Incomplete | G10: Low | H10: 2025-12-11 | J10: =IF(I10="","",I10-H10) | K10: 3 | L10: =IF(J10="","N/A",IF(J10<=K10,"Yes","No")) -> N/A | M10: Pending
A11: APP0008 | B11: CUST0008 | C11: Sanjay Malhotra | D11: Individual | E11: PAN, Aadhaar, Photo, Income Proof | F11: Failed | G11: Low | H11: 2025-12-15 | I11: 2025-12-16 | J11: =IF(I11="","",I11-H11) -> 1 | K11: 3 | L11: =IF(J11="","N/A",IF(J11<=K11,"Yes","No")) -> Yes | M11: Rejected | N11: Document authenticity could not be confirmed
A12: APP0009 | B12: CUST0009 | C12: Sneha Reddy | D12: Individual | E12: PAN, Aadhaar, Photo, Income Proof | F12: Verified | G12: Low | H12: 2025-12-11 | I12: 2025-12-12 | J12: =IF(I12="","",I12-H12) -> 1 | K12: 3 | L12: =IF(J12="","N/A",IF(J12<=K12,"Yes","No")) -> Yes | M12: Approved
A13: APP0010 | B13: CUST0010 | C13: Neha Singh | D13: Individual | E13: PAN, Aadhaar, Photo, Income Proof | F13: Verified | G13: Medium | H13: 2025-11-26 | I13: 2025-12-02 | J13: =IF(I13="","",I13-H13) -> 6 | K13: 5 | L13: =IF(J13="","N/A",IF(J13<=K13,"Yes","No")) -> No | M13: Approved
A14: APP0011 | B14: CUST0011 | C14: Bhavna Chopra | D14: Individual | E14: Aadhaar, Photo (PAN missing) | F14: Incomplete | G14: High | H14: 2025-11-10 | J14: =IF(I14="","",I14-H14) | K14: 7 | L14: =IF(J14="","N/A",IF(J14<=K14,"Yes","No")) -> N/A | M14: Pending
A15: APP0012 | B15: CUST0012 | C15: Prime Steel Traders | D15: Corporate | E15: PAN, COI, GST Certificate (Board Resolution pending) | F15: Incomplete | G15: Medium | H15: 2025-12-18 | J15: =IF(I15="","",I15-H15) | K15: 5 | L15: =IF(J15="","N/A",IF(J15<=K15,"Yes","No")) -> N/A | M15: Pending
A16: APP0013 | B16: CUST0013 | C16: Simran Chopra | D16: Individual | E16: PAN, Aadhaar, Address Proof | F16: Verified | G16: Low | H16: 2025-12-03 | I16: 2025-12-10 | J16: =IF(I16="","",I16-H16) -> 7 | K16: 3 | L16: =IF(J16="","N/A",IF(J16<=K16,"Yes","No")) -> No | M16: Approved
A17: APP0014 | B17: CUST0014 | C17: Ritu Reddy | D17: Individual | E17: Aadhaar, Photo (PAN missing) | F17: Incomplete | G17: Medium | H17: 2025-12-09 | J17: =IF(I17="","",I17-H17) | K17: 5 | L17: =IF(J17="","N/A",IF(J17<=K17,"Yes","No")) -> N/A | M17: Pending
A18: APP0015 | B18: CUST0015 | C18: Vertex Auto Components | D18: Corporate | E18: PAN, COI, Address Proof, Authorised Signatory ID | F18: Verified | G18: Medium | H18: 2025-12-04 | I18: 2025-12-05 | J18: =IF(I18="","",I18-H18) -> 1 | K18: 5 | L18: =IF(J18="","N/A",IF(J18<=K18,"Yes","No")) -> Yes | M18: Approved
A19: APP0016 | B19: CUST0016 | C19: Everest Handicrafts Pvt Ltd | D19: Corporate | E19: PAN, COI, GST Certificate (Board Resolution pending) | F19: Incomplete | G19: Medium | H19: 2025-11-08 | J19: =IF(I19="","",I19-H19) | K19: 5 | L19: =IF(J19="","N/A",IF(J19<=K19,"Yes","No")) -> N/A | M19: Pending
A20: APP0017 | B20: CUST0017 | C20: Sunrise Foods Pvt Ltd | D20: Corporate | E20: PAN, COI, GST Certificate (Board Resolution pending) | F20: Incomplete | G20: Low | H20: 2025-12-03 | J20: =IF(I20="","",I20-H20) | K20: 3 | L20: =IF(J20="","N/A",IF(J20<=K20,"Yes","No")) -> N/A | M20: Pending
A21: APP0018 | B21: CUST0018 | C21: Gaurav Iyer | D21: Individual | E21: PAN, Aadhaar, Photo, Income Proof | F21: Verified | G21: High | H21: 2025-12-24 | I21: 2025-12-29 | J21: =IF(I21="","",I21-H21) -> 5 | K21: 7 | L21: =IF(J21="","N/A",IF(J21<=K21,"Yes","No")) -> Yes | M21: Approved
A22: APP0019 | B22: CUST0019 | C22: Orchid Pharma Distributors | D22: Corporate | E22: PAN, COI, Board Resolution, Address Proof | F22: Verified | G22: Low | H22: 2025-12-09 | I22: 2025-12-16 | J22: =IF(I22="","",I22-H22) -> 7 | K22: 3 | L22: =IF(J22="","N/A",IF(J22<=K22,"Yes","No")) -> No | M22: Approved
A23: APP0020 | B23: CUST0020 | C23: Nisha Singh | D23: Individual | E23: PAN, Aadhaar, Photo | F23: Verified | G23: Low | H23: 2025-11-06 | I23: 2025-11-09 | J23: =IF(I23="","",I23-H23) -> 3 | K23: 3 | L23: =IF(J23="","N/A",IF(J23<=K23,"Yes","No")) -> Yes | M23: Approved
A24: APP0021 | B24: CUST0021 | C24: Rajeev Nair | D24: Individual | E24: Aadhaar, Photo (PAN missing) | F24: Incomplete | G24: Low | H24: 2025-12-06 | J24: =IF(I24="","",I24-H24) | K24: 3 | L24: =IF(J24="","N/A",IF(J24<=K24,"Yes","No")) -> N/A | M24: Pending
A25: APP0022 | B25: CUST0022 | C25: Horizon Tech Solutions | D25: Corporate | E25: PAN, COI, Address Proof, Authorised Signatory ID | F25: Failed | G25: High | H25: 2025-11-14 | I25: 2025-11-21 | J25: =IF(I25="","",I25-H25) -> 7 | K25: 7 | L25: =IF(J25="","N/A",IF(J25<=K25,"Yes","No")) -> Yes | M25: Rejected | N25: Customer did not respond to verification query
A26: APP0023 | B26: CUST0023 | C26: Shalini Rao | D26: Individual | E26: Aadhaar, Photo (PAN missing) | F26: Incomplete | G26: High | H26: 2025-11-08 | J26: =IF(I26="","",I26-H26) | K26: 7 | L26: =IF(J26="","N/A",IF(J26<=K26,"Yes","No")) -> N/A | M26: Pending
A27: APP0024 | B27: CUST0024 | C27: Bluewave Logistics Pvt Ltd | D27: Corporate | E27: PAN, COI, GST Certificate, Board Resolution | F27: Verified | G27: Low | H27: 2025-12-08 | I27: 2025-12-09 | J27: =IF(I27="","",I27-H27) -> 1 | K27: 3 | L27: =IF(J27="","N/A",IF(J27<=K27,"Yes","No")) -> Yes | M27: Approved
A28: APP0025 | B28: CUST0025 | C28: Rahul Gupta | D28: Individual | E28: PAN, Aadhaar, Photo, Income Proof | F28: Verified | G28: High | H28: 2025-11-05 | I28: 2025-11-11 | J28: =IF(I28="","",I28-H28) -> 6 | K28: 7 | L28: =IF(J28="","N/A",IF(J28<=K28,"Yes","No")) -> Yes | M28: Approved
A29: APP0026 | B29: CUST0026 | C29: Vivek Agarwal | D29: Individual | E29: Aadhaar, Photo (PAN missing) | F29: Incomplete | G29: Low | H29: 2025-12-22 | J29: =IF(I29="","",I29-H29) | K29: 3 | L29: =IF(J29="","N/A",IF(J29<=K29,"Yes","No")) -> N/A | M29: Pending
A30: APP0027 | B30: CUST0027 | C30: Arjun Iyer | D30: Individual | E30: PAN, Aadhaar, Photo, Income Proof | F30: Verified | G30: Medium | H30: 2025-11-28 | I30: 2025-12-05 | J30: =IF(I30="","",I30-H30) -> 7 | K30: 5 | L30: =IF(J30="","N/A",IF(J30<=K30,"Yes","No")) -> No | M30: Approved
A31: APP0028 | B31: CUST0028 | C31: Falcon Freight Services | D31: Corporate | E31: PAN, COI, Board Resolution, Address Proof | F31: Verified | G31: High | H31: 2025-11-04 | I31: 2025-11-09 | J31: =IF(I31="","",I31-H31) -> 5 | K31: 7 | L31: =IF(J31="","N/A",IF(J31<=K31,"Yes","No")) -> Yes | M31: Approved
A32: APP0029 | B32: CUST0029 | C32: Coastal Shipping Agency | D32: Corporate | E32: PAN, COI, GST Certificate, Board Resolution | F32: Verified | G32: Low | H32: 2025-11-18 | I32: 2025-11-24 | J32: =IF(I32="","",I32-H32) -> 6 | K32: 3 | L32: =IF(J32="","N/A",IF(J32<=K32,"Yes","No")) -> No | M32: Approved
A33: APP0030 | B33: CUST0030 | C33: Crimson Retail Ventures | D33: Corporate | E33: PAN, COI, Board Resolution, Address Proof | F33: Failed | G33: Low | H33: 2025-11-06 | I33: 2025-11-09 | J33: =IF(I33="","",I33-H33) -> 3 | K33: 3 | L33: =IF(J33="","N/A",IF(J33<=K33,"Yes","No")) -> Yes | M33: Rejected | N33: Address proof did not match application details
A34: APP0031 | B34: CUST0031 | C34: Preeti Verma | D34: Individual | E34: PAN, Aadhaar, Photo | F34: Verified | G34: Low | H34: 2025-11-25 | I34: 2025-11-27 | J34: =IF(I34="","",I34-H34) -> 2 | K34: 3 | L34: =IF(J34="","N/A",IF(J34<=K34,"Yes","No")) -> Yes | M34: Approved
A35: APP0032 | B35: CUST0032 | C35: Komal Saxena | D35: Individual | E35: Aadhaar, Photo (PAN missing) | F35: Incomplete | G35: Medium | H35: 2025-11-10 | J35: =IF(I35="","",I35-H35) | K35: 5 | L35: =IF(J35="","N/A",IF(J35<=K35,"Yes","No")) -> N/A | M35: Pending
A36: APP0033 | B36: CUST0033 | C36: Greenfield Agro Pvt Ltd | D36: Corporate | E36: PAN, COI, Board Resolution, Address Proof | F36: Verified | G36: High | H36: 2025-12-18 | I36: 2025-12-26 | J36: =IF(I36="","",I36-H36) -> 8 | K36: 7 | L36: =IF(J36="","N/A",IF(J36<=K36,"Yes","No")) -> No | M36: Approved
A37: APP0034 | B37: CUST0034 | C37: Neha Menon | D37: Individual | E37: PAN, Aadhaar, Address Proof | F37: Verified | G37: Low | H37: 2025-11-05 | I37: 2025-11-08 | J37: =IF(I37="","",I37-H37) -> 3 | K37: 3 | L37: =IF(J37="","N/A",IF(J37<=K37,"Yes","No")) -> Yes | M37: Approved
A38: APP0035 | B38: CUST0035 | C38: Trident Exports Pvt Ltd | D38: Corporate | E38: PAN, COI, GST Certificate, Board Resolution | F38: Verified | G38: High | H38: 2025-12-08 | I38: 2025-12-13 | J38: =IF(I38="","",I38-H38) -> 5 | K38: 7 | L38: =IF(J38="","N/A",IF(J38<=K38,"Yes","No")) -> Yes | M38: Approved
A39: APP0036 | B39: CUST0036 | C39: Karan Patel | D39: Individual | E39: PAN, Aadhaar, Photo, Income Proof | F39: Verified | G39: Medium | H39: 2025-11-16 | I39: 2025-11-19 | J39: =IF(I39="","",I39-H39) -> 3 | K39: 5 | L39: =IF(J39="","N/A",IF(J39<=K39,"Yes","No")) -> Yes | M39: Approved
A40: APP0037 | B40: CUST0037 | C40: Tanvi Kapoor | D40: Individual | E40: PAN, Aadhaar, Photo | F40: Verified | G40: High | H40: 2025-11-01 | I40: 2025-11-13 | J40: =IF(I40="","",I40-H40) -> 12 | K40: 7 | L40: =IF(J40="","N/A",IF(J40<=K40,"Yes","No")) -> No | M40: Approved
A41: APP0038 | B41: CUST0038 | C41: Maple Consulting LLP | D41: Corporate | E41: PAN, COI, GST Certificate (Board Resolution pending) | F41: Incomplete | G41: Low | H41: 2025-11-05 | J41: =IF(I41="","",I41-H41) | K41: 3 | L41: =IF(J41="","N/A",IF(J41<=K41,"Yes","No")) -> N/A | M41: Pending
...

Sheet Payment Processing
A1: PAYMENT PROCESSING - Transaction Register
A3: Transaction ID | B3: Customer ID | C3: Payment Type | D3: Amount (INR) | E3: Maker | F3: Checker | G3: Approval Status | H3: Payment Status | I3: Processing TAT (Days) | J3: Payment Date
A4: TXN00001 | B4: CUST0018 | C4: UPI | D4: 34895 | E4: Ops Analyst - A. Verma | F4: Ops Supervisor - K. Das | G4: Approved | H4: Success | I4: 1.2 | J4: 2025-12-28
A5: TXN00002 | B5: CUST0027 | C5: NEFT | D5: 273132 | E5: Ops Analyst - A. Verma | F5: Ops Supervisor - T. Singh | G5: Approved | H5: Success | I5: 1.1 | J5: 2025-12-13
A6: TXN00003 | B6: CUST0001 | C6: IMPS | D6: 142151 | E6: Ops Analyst - R. Nair | F6: Ops Supervisor - T. Singh | G6: Approved | H6: Success | I6: 1 | J6: 2025-12-28
A7: TXN00004 | B7: CUST0020 | C7: NEFT | D7: 70339 | E7: Ops Analyst - S. Iyer | F7: Ops Supervisor - V. Menon | G7: Approved | H7: Success | I7: 0.6 | J7: 2025-12-20
A8: TXN00005 | B8: CUST0040 | C8: UPI | D8: 16783 | E8: Ops Analyst - R. Nair | F8: Ops Supervisor - T. Singh | G8: Approved | H8: Success | I8: 1.4 | J8: 2025-12-25
A9: TXN00006 | B9: CUST0035 | C9: IMPS | D9: 107450 | E9: Ops Analyst - M. Rao | F9: Ops Supervisor - K. Das | G9: Approved | H9: Success | I9: 0.7 | J9: 2025-12-20
A10: TXN00007 | B10: CUST0034 | C10: NEFT | D10: 173951 | E10: Ops Analyst - P. Kapoor | F10: Ops Supervisor - T. Singh | G10: Approved | H10: Success | I10: 0.8 | J10: 2025-12-29
A11: TXN00008 | B11: CUST0044 | C11: RTGS | D11: 1623474 | E11: Ops Analyst - A. Verma | F11: Ops Supervisor - T. Singh | G11: Approved | H11: Success | I11: 1 | J11: 2026-01-02
A12: TXN00009 | B12: CUST0004 | C12: RTGS | D12: 2170220 | E12: Ops Analyst - S. Iyer | F12: Ops Supervisor - K. Das | G12: Approved | H12: Success | I12: 0.2 | J12: 2025-12-13
A13: TXN00010 | B13: CUST0029 | C13: NEFT | D13: 43182 | E13: Ops Analyst - P. Kapoor | F13: Ops Supervisor - T. Singh | G13: Approved | H13: Success | I13: 0.6 | J13: 2025-12-13
A14: TXN00011 | B14: CUST0025 | C14: UPI | D14: 86090 | E14: Ops Analyst - A. Verma | F14: Ops Supervisor - K. Das | G14: Approved | H14: Success | I14: 1.2 | J14: 2025-12-28
A15: TXN00012 | B15: CUST0040 | C15: IMPS | D15: 14164 | E15: Ops Analyst - M. Rao | F15: Ops Supervisor - K. Das | G15: Approved | H15: Success | I15: 1.2 | J15: 2025-12-08
... A52: TXN00049 | B52: CUST0004 | C52: UPI | D52: 53645 | E52: Ops Analyst - P. Kapoor | F52: Ops Supervisor - V. Menon | G52: Approved | H52: Success | I52: 0.4 | J52: 2025-12-31
A53: TXN00050 | B53: CUST0040 | C53: UPI | D53: 59610 | E53: Ops Analyst - A. Verma | F53: Ops Supervisor - V. Menon | G53: Pending | H53: Pending | J53: 2025-12-15
A54: TXN00051 | B54: CUST0044 | C54: NEFT | D54: 108714 | E54: Ops Analyst - P. Kapoor | F54: Ops Supervisor - K. Das | G54: Approved | H54: Success | I54: 0.3 | J54: 2026-01-04
A55: TXN00052 | B55: CUST0018 | C55: RTGS | D55: 799029 | E55: Ops Analyst - A. Verma | F55: Ops Supervisor - K. Das | G55: Approved | H55: Success | I55: 1.3 | J55: 2025-12-20
A56: TXN00053 | B56: CUST0049 | C56: UPI | D56: 16399 | E56: Ops Analyst - P. Kapoor | F56: Ops Supervisor - V. Menon | G56: Approved | H56: Success | I56: 1.4 | J56: 2025-12-20
A57: TXN00054 | B57: CUST0031 | C57: IMPS | D57: 115755 | E57: Ops Analyst - A. Verma | F57: Ops Supervisor - V. Menon | G57: Approved | H57: Failed | I57: 1.5 | J57: 2025-12-03
A58: TXN00055 | B58: CUST0035 | C58: UPI | D58: 12070 | E58: Ops Analyst - R. Nair | F58: Ops Supervisor - V. Menon | G58: Approved | H58: Reversed | I58: 2.2 | J58: 2025-12-02
A59: TXN00056 | B59: CUST0018 | C59: IMPS | D59: 199251 | E59: Ops Analyst - R. Nair | F59: Ops Supervisor - T. Singh | G59: Approved | H59: Success | I59: 1.4 | J59: 2026-01-03
A60: TXN00057 | B60: CUST0010 | C60: SWIFT | D60: 964117 | E60: Ops Analyst - P. Kapoor | F60: Ops Supervisor - K. Das | G60: Approved | H60: Success | I60: 0.6 | J60: 2025-12-31
A61: TXN00058 | B61: CUST0037 | C61: UPI | D61: 21179 | E61: Ops Analyst - S. Iyer | F61: Ops Supervisor - T. Singh | G61: Approved | H61: Success | I61: 1.4 | J61: 2026-01-01
A62: TXN00059 | B62: CUST0045 | C62: NEFT | D62: 24239 | E62: Ops Analyst - P. Kapoor | F62: Ops Supervisor - K. Das | G62: Approved | H62: Success | I62: 0.3 | J62: 2025-12-21
A63: TXN00060 | B63: CUST0042 | C63: IMPS | D63: 135898 | E63: Ops Analyst - A. Verma | F63: Ops Supervisor - V. Menon | G63: Approved | H63: Success | I63: 0.2 | J63: 2026-01-04
A64: TXN00061 | B64: CUST0031 | C64: IMPS | D64: 199297 | E64: Ops Analyst - P. Kapoor | F64: Ops Supervisor - V. Menon | G64: Approved | H64: Success | I64: 0.4 | J64: 2025-12-29
A65: TXN00062 | B65: CUST0033 | C65: UPI | D65: 37852 | E65: Ops Analyst - P. Kapoor | F65: Ops Supervisor - V. Menon | G65: Approved | H65: Success | I65: 1.5 | J65: 2026-01-01
... A118: TXN00115 | B118: CUST0044 | C118: IMPS | D118: 148053 | E118: Ops Analyst - M. Rao | F118: Ops Supervisor - V. Menon | G118: Approved | H118: Success | I118: 1.4 | J118: 2026-01-05
A119: TXN00116 | B119: CUST0045 | C119: NEFT | D119: 20179 | E119: Ops Analyst - R. Nair | F119: Ops Supervisor - T. Singh | G119: Pending | H119: Pending | J119: 2025-12-20
A120: TXN00117 | B120: CUST0024 | C120: UPI | D120: 18876 | E120: Ops Analyst - M. Rao | F120: Ops Supervisor - V. Menon | G120: Approved | H120: Success | I120: 1.1 | J120: 2025-12-26
A121: TXN00118 | B121: CUST0001 | C121: UPI | D121: 69631 | E121: Ops Analyst - R. Nair | F121: Ops Supervisor - T. Singh | G121: Approved | H121: Success | I121: 0.3 | J121: 2025-12-27
A122: TXN00119 | B122: CUST0019 | C122: NEFT | D122: 49541 | E122: Ops Analyst - A. Verma | F122: Ops Supervisor - K. Das | G122: Approved | H122: Success | I122: 0.2 | J122: 2025-12-11
A123: TXN00120 | B123: CUST0004 | C123: UPI | D123: 86861 | E123: Ops Analyst - P. Kapoor | F123: Ops Supervisor - T. Singh | G123: Approved | H123: Success | I123: 0.4 | J123: 2025-12-29

Sheet Exception Management
A1: EXCEPTION MANAGEMENT - Exception Queue (linked to Payment Processing)
A3: Exception ID | B3: Linked Transaction ID | C3: Exception Category | D3: Root Cause | E3: Resolution Action | F3: Owner | G3: Resolution TAT (Days) | H3: Current Status
A4: EXC001 | B4: TXN00045 | C4: Beneficiary Validation Failure | D4: Beneficiary name did not match bank records | E4: Escalated | F4: Compliance Team | H4: Pending
A5: EXC002 | B5: TXN00029 | C5: Wrong IFSC | D5: IFSC code did not match beneficiary bank branch | E5: Manual Correction | F5: Operations Team | H5: Pending
A6: EXC003 | B6: TXN00044 | C6: Beneficiary Validation Failure | D6: Beneficiary name did not match bank records | E6: Escalated | F6: Compliance Team | G6: 0.5 | H6: Resolved
A7: EXC004 | B7: TXN00084 | C7: Insufficient Funds | D7: Customer account did not have sufficient balance at processing time | E7: Retry | F7: Operations Team | G7: 1.8 | H7: Resolved
A8: EXC005 | B8: TXN00112 | C8: Wrong IFSC | D8: IFSC code did not match beneficiary bank branch | E8: Manual Correction | F8: Operations Team | G8: 3.4 | H8: Resolved
A9: EXC006 | B9: TXN00094 | C9: Beneficiary Validation Failure | D9: Beneficiary name did not match bank records | E9: Escalated | F9: Compliance Team | G9: 3.5 | H9: Resolved
A10: EXC007 | B10: TXN00021 | C10: Duplicate Payment | D10: Same payment instruction submitted twice by customer | E10: Reversal | F10: Operations Team | G10: 2.1 | H10: Resolved
A11: EXC008 | B11: TXN00018 | C11: Invalid Account Number | D11: Customer entered incorrect beneficiary account number | E11: Manual Correction | F11: Operations Team | H11: Pending
A12: EXC009 | B12: TXN00089 | C12: Network Timeout | D12: Payment gateway timeout during transaction processing | E12: Retry | F12: Operations Team | G12: 1.9 | H12: Resolved
A13: EXC010 | B13: TXN00050 | C13: Sanctions Hold | D13: Transaction held for sanctions screening review | E13: Escalated | F13: Compliance Team | G13: 0.9 | H13: Resolved
A14: EXC011 | B14: TXN00046 | C14: Invalid Account Number | D14: Customer entered incorrect beneficiary account number | E14: Manual Correction | F14: Operations Team | H14: Pending
A15: EXC012 | B15: TXN00054 | C15: Wrong IFSC | D15: IFSC code did not match beneficiary bank branch | E15: Manual Correction | F15: Operations Team | H15: Pending
A16: EXC013 | B16: TXN00116 | C16: Sanctions Hold | D16: Transaction held for sanctions screening review | E16: Escalated | F16: Compliance Team | G16: 2.9 | H16: Resolved
A17: EXC014 | B17: TXN00055 | C17: Reversed Payment | D17: Payment reversed after beneficiary bank rejected credit | E17: Reversal | F17: Operations Team | G17: 3.5 | H17: Resolved
A18: EXC015 | B18: TXN00041 | C18: Wrong IFSC | D18: IFSC code did not match beneficiary bank branch | E18: Manual Correction | F18: Operations Team | G18: 1.9 | H18: Resolved
A19: EXC016 | B19: TXN00114 | C19: Invalid Account Number | D19: Customer entered incorrect beneficiary account number | E19: Manual Correction | F19: Operations Team | G19: 1.6 | H19: Resolved
A20: EXC017 | B20: TXN00088 | C20: Beneficiary Validation Failure | D20: Beneficiary name did not match bank records | E20: Escalated | F20: Compliance Team | G20: 3.2 | H20: Resolved
A21: EXC018 | B21: TXN00066 | C21: Invalid Account Number | D21: Customer entered incorrect beneficiary account number | E21: Manual Correction | F21: Operations Team | G21: 0.9 | H21: Resolved
A22: EXC019 | B22: TXN00032 | C22: Network Timeout | D22: Payment gateway timeout during transaction processing | E22: Retry | F22: Operations Team | G22: 3.2 | H22: Resolved
A23: EXC020 | B23: TXN00095 | C23: Beneficiary Validation Failure | D23: Beneficiary name did not match bank records | E23: Escalated | F23: Compliance Team | G23: 3.4 | H23: Resolved

Sheet Operations Dashboard
A1: BANKING OPERATIONS DASHBOARD
A2: Client Onboarding | Payment Processing | Exception Management
A4: Total Applications | C4: Applications Approved | E4: Applications Pending | G4: Applications Rejected
A5: =COUNTA('Client Onboarding'!A4:A53) -> 50 | C5: =COUNTIF('Client Onboarding'!M4:M53,"Approved") -> 30 | E5: =COUNTIF('Client Onboarding'!M4:M53,"Pending") -> 15 | G5: =COUNTIF('Client Onboarding'!M4:M53,"Rejected") -> 5
A7: Approval Rate | C7: Avg Onboarding TAT (Days) | E7: SLA Compliance % | G7: Payments Processed
A8: =C5/A5 -> 0.6 | C8: =AVERAGE('Client Onboarding'!J4:J53) -> 4.6 | E8: =COUNTIF('Client Onboarding'!L4:L53,"Yes")/(COUNTIF('Client Onboarding'!L4:L53,"Yes")+COUNTIF('Client Onboarding'!L4:L53,"No")) -> 0.65714286 | G8: =COUNTA('Payment Processing'!A4:A123) -> 120
A10: Payment Success Rate | C10: Failed Payments | E10: Pending Payments | G10: Reversed Payments
A11: =COUNTIF('Payment Processing'!H4:H123,"Success")/G8 -> 0.83333333 | C11: =COUNTIF('Payment Processing'!H4:H123,"Failed") -> 16 | E11: =COUNTIF('Payment Processing'!H4:H123,"Pending") -> 2 | G11: =COUNTIF('Payment Processing'!H4:H123,"Reversed") -> 2
A13: Total Exceptions | C13: Avg Resolution TAT (Days) | E13: Exceptions Resolved | G13: Exceptions Pending
A14: =COUNTA('Exception Management'!A4:A23) -> 20 | C14: =AVERAGE('Exception Management'!G4:G23) -> 2.3133333 | E14: =COUNTIF('Exception Management'!H4:H23,"Resolved") -> 15 | G14: =COUNTIF('Exception Management'!H4:H23,"Pending") -> 5
A17: Chart Data Tables (supporting the visuals below)
A18: Approval Status | B18: Count | D18: Payment Status | E18: Count | G18: Exception Category | H18: Count
A19: Approved | B19: =COUNTIF('Client Onboarding'!M4:M53,"Approved") -> 30 | D19: Success | E19: =COUNTIF('Payment Processing'!H4:H123,"Success") -> 100 | G19: Invalid Account Number | H19: =COUNTIF('Exception Management'!C4:C23,"Invalid Account Number") -> 4
A20: Rejected | B20: =COUNTIF('Client Onboarding'!M4:M53,"Rejected") -> 5 | D20: Failed | E20: =COUNTIF('Payment Processing'!H4:H123,"Failed") -> 16 | G20: Wrong IFSC | H20: =COUNTIF('Exception Management'!C4:C23,"Wrong IFSC") -> 4
A21: Pending | B21: =COUNTIF('Client Onboarding'!M4:M53,"Pending") -> 15 | D21: Pending | E21: =COUNTIF('Payment Processing'!H4:H123,"Pending") -> 2 | G21: Beneficiary Validation Failure | H21: =COUNTIF('Exception Management'!C4:C23,"Beneficiary Validation Failure") -> 5
D22: Reversed | E22: =COUNTIF('Payment Processing'!H4:H123,"Reversed") -> 2 | G22: Insufficient Funds | H22: =COUNTIF('Exception Management'!C4:C23,"Insufficient Funds") -> 1
G23: Network Timeout | H23: =COUNTIF('Exception Management'!C4:C23,"Network Timeout") -> 2
G24: Duplicate Payment | H24: =COUNTIF('Exception Management'!C4:C23,"Duplicate Payment") -> 1
G25: Reversed Payment | H25: =COUNTIF('Exception Management'!C4:C23,"Reversed Payment") -> 1
G26: Sanctions Hold | H26: =COUNTIF('Exception Management'!C4:C23,"Sanctions Hold") -> 2
A29: Payment Type | B29: Avg TAT (Days) | D29: Exception Category | E29: Avg Resolution TAT
A30: UPI | B30: =IFERROR(AVERAGEIFS('Payment Processing'!I4:I123,'Payment Processing'!C4:C123,"UPI",'Payment Processing'!H4:H123,"Success"),0) -> 0.78378378 | D30: Invalid Account Number | E30: =IFERROR(AVERAGEIFS('Exception Management'!G4:G23,'Exception Management'!C4:C23,"Invalid Account Number",'Exception Management'!H4:H23,"Resolved"),0) -> 1.25
A31: IMPS | B31: =IFERROR(AVERAGEIFS('Payment Processing'!I4:I123,'Payment Processing'!C4:C123,"IMPS",'Payment Processing'!H4:H123,"Success"),0) -> 0.9375 | D31: Wrong IFSC | E31: =IFERROR(AVERAGEIFS('Exception Management'!G4:G23,'Exception Management'!C4:C23,"Wrong IFSC",'Exception Management'!H4:H23,"Resolved"),0) -> 2.65
A32: NEFT | B32: =IFERROR(AVERAGEIFS('Payment Processing'!I4:I123,'Payment Processing'!C4:C123,"NEFT",'Payment Processing'!H4:H123,"Success"),0) -> 0.69583333 | D32: Beneficiary Validation Failure | E32: =IFERROR(AVERAGEIFS('Exception Management'!G4:G23,'Exception Management'!C4:C23,"Beneficiary Validation Failure",'Exception Management'!H4:H23,"Resolved"),0) -> 2.65
A33: RTGS | B33: =IFERROR(AVERAGEIFS('Payment Processing'!I4:I123,'Payment Processing'!C4:C123,"RTGS",'Payment Processing'!H4:H123,"Success"),0) -> 0.89 | D33: Insufficient Funds | E33: =IFERROR(AVERAGEIFS('Exception Management'!G4:G23,'Exception Management'!C4:C23,"Insufficient Funds",'Exception Management'!H4:H23,"Resolved"),0) -> 1.8
A34: SWIFT | B34: =IFERROR(AVERAGEIFS('Payment Processing'!I4:I123,'Payment Processing'!C4:C123,"SWIFT",'Payment Processing'!H4:H123,"Success"),0) -> 0.78 | D34: Network Timeout | E34: =IFERROR(AVERAGEIFS('Exception Management'!G4:G23,'Exception Management'!C4:C23,"Network Timeout",'Exception Management'!H4:H23,"Resolved"),0) -> 2.55
D35: Duplicate Payment | E35: =IFERROR(AVERAGEIFS('Exception Management'!G4:G23,'Exception Management'!C4:C23,"Duplicate Payment",'Exception Management'!H4:H23,"Resolved"),0) -> 2.1
D36: Reversed Payment | E36: =IFERROR(AVERAGEIFS('Exception Management'!G4:G23,'Exception Management'!C4:C23,"Reversed Payment",'Exception Management'!H4:H23,"Resolved"),0) -> 3.5
D37: Sanctions Hold | E37: =IFERROR(AVERAGEIFS('Exception Management'!G4:G23,'Exception Management'!C4:C23,"Sanctions Hold",'Exception Management'!H4:H23,"Resolved"),0) -> 1.9
A41: LOOKUP TOOLS — Customer Search (demonstrates XLOOKUP & INDEX-MATCH)
A42: Tip: change the Customer ID above to search any onboarding record instantly.
A43: Enter Customer ID: | B43: CUST0007
A45: Customer Name (INDEX-MATCH) | B45: =INDEX('Client Onboarding'!$C$4:$C$53,MATCH($B$43,'Client Onboarding'!$B$4:$B$53,0)) -> Rahul Iyer
A46: Customer Type (INDEX-MATCH) | B46: =INDEX('Client Onboarding'!$D$4:$D$53,MATCH($B$43,'Client Onboarding'!$B$4:$B$53,0)) -> Individual
A47: Risk Category (INDEX-MATCH) | B47: =INDEX('Client Onboarding'!$G$4:$G$53,MATCH($B$43,'Client Onboarding'!$B$4:$B$53,0)) -> Low
A48: Final Status (INDEX-MATCH) | B48: =INDEX('Client Onboarding'!$M$4:$M$53,MATCH($B$43,'Client Onboarding'!$B$4:$B$53,0)) -> Pending
A51: PAYMENT VOLUME BY TYPE — Successful Payments (SUMIFS)
A52: Payment Type | B52: Total Amount (INR) | C52: Transaction Count
A53: UPI | B53: =SUMIFS('Payment Processing'!$D$4:$D$123,'Payment Processing'!$C$4:$C$123,A53,'Payment Processing'!$H$4:$H$123,"Success") -> 1827846 | C53: =COUNTIFS('Payment Processing'!$C$4:$C$123,A53,'Payment Processing'!$H$4:$H$123,"Success") -> 37
A54: IMPS | B54: =SUMIFS('Payment Processing'!$D$4:$D$123,'Payment Processing'!$C$4:$C$123,A54,'Payment Processing'!$H$4:$H$123,"Success") -> 2935631 | C54: =COUNTIFS('Payment Processing'!$C$4:$C$123,A54,'Payment Processing'!$H$4:$H$123,"Success") -> 24
...

Sheet Audit Trail
A1: AUDIT TRAIL - Governance & Status Change Log
A3: Audit ID | B3: Record ID | C3: Module | D3: Action | E3: Performed By | F3: Timestamp | G3: Previous Status | H3: New Status | I3: Reason
A4: AUD001 | B4: APP0031 | C4: Client Onboarding | D4: Status Updated | E4: Ops Supervisor - K. Das | F4: 2025-11-27 16:00 | G4: Pending | H4: Approved | I4: Verification completed by checker
A5: AUD002 | B5: APP0009 | C5: Client Onboarding | D5: Status Updated | E5: Ops Supervisor - T. Singh | F5: 2025-12-12 10:00 | G5: Pending | H5: Approved | I5: Verification completed by checker
A6: AUD003 | B6: TXN00054 | C6: Payment Processing | D6: Status Updated | E6: Ops Supervisor - T. Singh | F6: 2025-12-03 16:00 | G6: Pending | H6: Failed | I6: Checker flagged transaction during approval review
A7: AUD004 | B7: APP0010 | C7: Client Onboarding | D7: Status Updated | E7: Compliance Officer - N. Bhatt | F7: 2025-12-02 16:00 | G7: Pending | H7: Approved | I7: Verification completed by checker
A8: AUD005 | B8: APP0049 | C8: Client Onboarding | D8: Status Updated | E8: Compliance Officer - N. Bhatt | F8: 2025-12-02 16:00 | G8: Pending | H8: Approved | I8: Verification completed by checker
A9: AUD006 | B9: APP0015 | C9: Client Onboarding | D9: Status Updated | E9: Ops Supervisor - K. Das | F9: 2025-12-05 14:00 | G9: Pending | H9: Approved | I9: Verification completed by checker
A10: AUD007 | B10: EXC007 | C10: Exception Management | D10: Exception Resolved | E10: Ops Analyst - R. Nair | F10: 2025-12-13 09:00 | G10: Pending | H10: Resolved | I10: Resolved via Reversal
A11: AUD008 | B11: EXC015 | C11: Exception Management | D11: Exception Resolved | E11: Compliance Officer - N. Bhatt | F11: 2025-12-23 10:00 | G11: Pending | H11: Resolved | I11: Resolved via Manual Correction
A12: AUD009 | B12: APP0027 | C12: Client Onboarding | D12: Status Updated | E12: Ops Supervisor - T. Singh | F12: 2025-12-05 11:00 | G12: Pending | H12: Approved | I12: Verification completed by checker
A13: AUD010 | B13: APP0046 | C13: Client Onboarding | D13: Status Updated | E13: Ops Supervisor - T. Singh | F13: 2026-01-02 11:00 | G13: Pending | H13: Approved | I13: Verification completed by checker
A14: AUD011 | B14: EXC010 | C14: Exception Management | D14: Exception Resolved | E14: Ops Supervisor - K. Das | F14: 2026-01-04 11:00 | G14: Pending | H14: Resolved | I14: Resolved via Escalated
... A23: AUD020 | B23: TXN00114 | C23: Payment Processing | D23: Status Updated | E23: Ops Analyst - A. Verma | F23: 2025-12-08 10:00 | G23: Pending | H23: Failed | I23: Checker flagged transaction during approval review

Sheet Business Rules
A1: BUSINESS RULES - Client Onboarding & Payment Processing
A3: # | B3: Business Rule
A4: 1 | B4: RTGS payments are permitted only for amounts above Rs 2,00,000.
A5: 2 | B5: Duplicate Transaction IDs are automatically rejected during payment processing.
A6: 3 | B6: Customers classified as High Risk require manual document verification before approval.
A7: 4 | B7: SWIFT payments require beneficiary bank validation before funds are released.
A8: 5 | B8: Any payment marked Failed, Pending, or Reversed is automatically moved to the Exception Queue.
A9: 6 | B9: An invalid or mismatched IFSC code results in payment rejection.
A10: 7 | B10: Incomplete documentation keeps an onboarding application in Pending status until resolved.
A11: 8 | B11: Rejected customers cannot initiate any payment transactions.
A12: 9 | B12: The Maker and Checker for a transaction must always be two different individuals.
A13: 10 | B13: Every logged exception must be assigned a Resolution Owner (Operations or Compliance Team).
A14: 11 | B14: Applications pending verification for more than the SLA target are flagged as SLA breaches.
A15: 12 | B15: Sanctions Hold exceptions are always routed to the Compliance Team, not Operations.
... A17: 14 | B17: A transaction cannot be approved without both Maker initiation and Checker approval recorded.
